<?xml version="1.0"?>
<!-- Open_Manipulator Chain -->
<robot name="open_manipulator" xmlns:xacro="http://ros.org/wiki/xacro">

  <!-- Import Rviz colors -->
  <xacro:include filename="$(find open_manipulator_description)/urdf/materials.xacro" />

  <!-- Import all Gazebo-customization elements, including Gazebo colors -->
  <xacro:include filename="$(find open_manipulator_description)/urdf/open_manipulator.gazebo.xacro" />

  <!-- Import Transmission -->
  <xacro:include filename="$(find open_manipulator_description)/urdf/open_manipulator.transmission.xacro" />

  <!-- Import URDF -->
  <xacro:include filename="$(find open_manipulator_description)/urdf/open_manipulator.urdf.xacro" />

  <!-- Link 1 -->
  <link name="link1">
    <visual>
      <origin xyz="0 0 0" rpy="0 0 0"/>
      <geometry>
        <mesh filename="package://open_manipulator_description/meshes/chain_link1.stl" scale="0.001 0.001 0.001"/>
      </geometry>
      <material name="grey"/>
    </visual>

    <collision>
      <origin xyz="0 0 0" rpy="0 0 0"/>
      <geometry>
        <mesh filename="package://open_manipulator_description/meshes/chain_link1.stl" scale="0.001 0.001 0.001"/>
      </geometry>
    </collision>

    <inertial>
      <origin xyz="3.0876154e-04 0.0000000e+00 -1.2176461e-04" />
      <mass value="7.9119962e-02" />
      <inertia ixx="1.2505234e-05" ixy="0.0" ixz="-1.7855208e-07"
               iyy="2.1898364e-05" iyz="0.0"
               izz="1.9267361e-05" />
    </inertial>
  </link>

  <!-- Joint 1 -->
  <joint name="joint1" type="revolute">
    <parent link="link1"/>
    <child link="link2"/>
    <origin xyz="0.012 0.0 0.017" rpy="0 0 0"/>
    <axis xyz="0 0 1"/>
    <limit velocity="4.8" effort="1" lower="${-pi*0.9}" upper="${pi*0.9}" />
  </joint>


  <!--  Link 2 -->
  <link name="link2">
    <visual>
      <origin xyz="0 0 0.019" rpy="0 0 0"/>
      <geometry>
        <mesh filename="package://open_manipulator_description/meshes/chain_link2.stl" scale="0.001 0.001 0.001"/>
      </geometry>
      <material name="grey"/>
    </visual>

    <collision>
      <origin xyz="0 0 0.019" rpy="0 0 0"/>
      <geometry>
        <mesh filename="package://open_manipulator_description/meshes/chain_link2.stl" scale="0.001 0.001 0.001"/>
      </geometry>
    </collision>

    <inertial>
      <origin xyz="-3.0184870e-04 5.4043684e-04 ${0.018 + 2.9433464e-02}" />
      <mass value="9.8406837e-02" />
      <inertia ixx="3.4543422e-05" ixy="-1.6031095e-08" ixz="-3.8375155e-07"
               iyy="3.2689329e-05" iyz="2.8511935e-08"
               izz="1.8850320e-05" />
    </inertial>
  </link>

  <!--  Joint 2 -->
  <joint name="joint2" type="revolute">
    <parent link="link2"/>
    <child link="link3"/>
    <origin xyz="0.0 0.0 0.0595" rpy="0 0 0"/>
    <axis xyz="0 1 0"/>
    <limit velocity="4.8" effort="1" lower="${-pi*0.57}" upper="${pi*0.5}" />
  </joint>


  <!-- World fixed joint-->
  <joint name="manipulator_joint" type="fixed">
    <origin xyz="0.075 0 0.05" rpy="0 0 0"/>
    <parent link="base"/>
    <child link="link1"/>
  </joint>

</robot>
